<?xml version='1.0'?>
<robot name="robo">

 
  <link name="base_link">
    <inertial>
      <mass value="5"/>
      <inertia ixx="0.13" ixy="0.0" ixz="0.0"
               iyy="0.21" iyz="0.0" izz="0.13"/>
    </inertial>
  <visual>
      <origin xyz="0 0 0" rpy="0 0 0" />
      <geometry>
        <box size="0.5 0.5 0.25"/>
      </geometry>
    </visual>
   <collision>
      <origin xyz="0 0 0" rpy="0 0 0" />
      <geometry>
        <box size="0.5 0.5 0.25"/>
      </geometry>
   </collision>
    
    <!--caster wheel -->
    
     <inertial>
      <mass value="0.5"/>
      <inertia ixx="0.0001" ixy="0.0" ixz="0.0"
               iyy="0.0001" iyz="0.0" izz="0.0001"/>
    </inertial>
    
    <visual name="caster">
      <origin xyz="0.2 0 -0.125" rpy="0 0 0" />
      <geometry>
        <sphere radius="0.05" />
      </geometry>
    </visual>
    
     <collision>
      <origin xyz="0.2 0 -0.125" rpy="0 0 0" />
      <geometry>
        <sphere radius="0.05" />
      </geometry>
    </collision>
        
  </link>

  <!-- Right Wheel -->
  <link name="right_wheel">
     <inertial>
      <mass value="0.5"/>
      <inertia ixx="0.01"  ixy="0.0" ixz="0.0"
               iyy="0.005" iyz="0.0" izz="0.005"/>
    </inertial>
  ...
    <visual>
      <origin xyz="0 0 0" rpy="1.570795 0 0" />
      <geometry>
        <cylinder length="0.1" radius="0.2" />
      </geometry>
    </visual>
    
     <collision>
      <origin xyz="0 0 0" rpy="1.570795 0 0" />
      <geometry>
        <cylinder length="0.1" radius="0.2" />
      </geometry>
    </collision>
  </link>
  
  <joint name="joint_right_wheel" type="continuous">
    <parent link="base_link"/>
    <child link="right_wheel"/>
    <origin xyz="0 -0.30 0" rpy="0 0 0" />
    <axis xyz="0 1 0" />
  </joint>

  <!-- Left Wheel -->
  <link name="left_wheel">
  
    <inertial>
      <mass value="0.5"/>
      <inertia ixx="0.01" ixy="0.0" ixz="0.0"
               iyy="0.005" iyz="0.0" izz="0.005"/>
    </inertial>
    <visual>
      <origin xyz="0 0 0" rpy="1.570795 0 0" />
      <geometry>
        <cylinder length="0.1" radius="0.2" />
      </geometry>
    </visual>
    
    <collision>
      <origin xyz="0 0 0" rpy="1.570795 0 0" />
      <geometry>
        <cylinder length="0.1" radius="0.2" />
      </geometry>
    </collision>
  </link>

  <joint name="joint_left_wheel" type="continuous">
    <parent link="base_link"/>
    <child link="left_wheel"/>
    <origin xyz="0 0.30 0" rpy="0 0 0" />
    <axis xyz="0 1 0" />
  </joint>

</robot>
